Workbook

Sheet Leia-me
A1: Amazônia em Números #1 — Desmatamento anual por bioma (INPE/PRODES)
A2: Organização: Marcela Paz da Silva Enriquez · github.com/marcelapazenriquez/amazonia-em-numeros
A4: O que tem nesta planilha
A5: 1. Tabela anual — anos nas linhas, biomas nas colunas. A mais fácil de ler.
A6: 2. Base longa — um registro por bioma e ano, com variação anual e filtros (igual ao arquivo prodes_biomas.csv).
A7: 3. Conferência — cada número citado no post, calculado por fórmula a partir da Tabela anual. Clique nas células para ver a conta.
A9: Fonte
A10: INPE/PRODES, painel "Incrementos de desmatamento" por bioma, no TerraBrasilis.
A11: Link: https://terrabrasilis.dpi.inpe.br/app/dashboard/deforestation/biomes/<bioma>/increments (<bioma> = amazon, cerrado, caatinga, mata_atlantica, pampa, pantanal)
A12: Passo a passo: abrir o link de cada bioma → gráfico "Incrementos de desmatamento" → menu ≡ → exportar CSV. Acesso em 16/10/2026.
A14: Como ler os números
A15: Unidade: km² de vegetação nativa suprimida por ano.
... A20: Valores de 2026 podem ser preliminares. Células vazias = sem dado no painel do INPE.

Sheet Tabela anual
A1: Ano | B1: Amazônia (floresta) | C1: Amazônia (não floresta) | D1: Cerrado | E1: Caatinga | F1: Mata Atlântica | G1: Pampa | H1: Pantanal | I1: Amazônia total (floresta + não floresta) | J1: Cerrado desmatou mais que a Amazônia?
A2: 2001 | C2: 1551.8 | D2: 26933.02 | E2: 12186.41 | F2: 5625.91 | G2: 2866 | H2: 1000.06 | I2: =IF(AND(ISNUMBER(B2),ISNUMBER(C2)),B2+C2,"") | J2: =IF(AND(A2>=2008,ISNUMBER(I2),ISNUMBER(D2)),IF(D2>I2,"Sim","Não"),"")
A3: 2002 | C3: 1551.8 | D3: 26933.02 | E3: 12186.41 | F3: 5625.91 | G3: 2866 | H3: 1000.06 | I3: =IF(AND(ISNUMBER(B3),ISNUMBER(C3)),B3+C3,"") | J3: =IF(AND(A3>=2008,ISNUMBER(I3),ISNUMBER(D3)),IF(D3>I3,"Sim","Não"),"")
A4: 2003 | C4: 1380.02 | D4: 28770.33 | E4: 12186.41 | F4: 5625.91 | G4: 2866 | H4: 1000.06 | I4: =IF(AND(ISNUMBER(B4),ISNUMBER(C4)),B4+C4,"") | J4: =IF(AND(A4>=2008,ISNUMBER(I4),ISNUMBER(D4)),IF(D4>I4,"Sim","Não"),"")
A5: 2004 | C5: 1380.02 | D5: 28770.33 | E5: 12186.41 | F5: 5625.91 | G5: 2866 | H5: 1000.06 | I5: =IF(AND(ISNUMBER(B5),ISNUMBER(C5)),B5+C5,"") | J5: =IF(AND(A5>=2008,ISNUMBER(I5),ISNUMBER(D5)),IF(D5>I5,"Sim","Não"),"")
A6: 2005 | C6: 941.24 | D6: 16877.45 | E6: 8172.6 | F6: 6384.15 | G6: 2004.36 | H6: 845.96 | I6: =IF(AND(ISNUMBER(B6),ISNUMBER(C6)),B6+C6,"") | J6: =IF(AND(A6>=2008,ISNUMBER(I6),ISNUMBER(D6)),IF(D6>I6,"Sim","Não"),"")
A7: 2006 | C7: 941.24 | D7: 16877.45 | E7: 8172.6 | F7: 6384.15 | G7: 2004.36 | H7: 845.96 | I7: =IF(AND(ISNUMBER(B7),ISNUMBER(C7)),B7+C7,"") | J7: =IF(AND(A7>=2008,ISNUMBER(I7),ISNUMBER(D7)),IF(D7>I7,"Sim","Não"),"")
A8: 2007 | C8: 581.53 | D8: 13311.56 | E8: 6351.46 | F8: 4004.42 | G8: 1449.72 | H8: 518.45 | I8: =IF(AND(ISNUMBER(B8),ISNUMBER(C8)),B8+C8,"") | J8: =IF(AND(A8>=2008,ISNUMBER(I8),ISNUMBER(D8)),IF(D8>I8,"Sim","Não"),"")
A9: 2008 | B9: 12398.68 | C9: 581.53 | D9: 13311.56 | E9: 6351.46 | F9: 4004.42 | G9: 1449.72 | H9: 518.45 | I9: =IF(AND(ISNUMBER(B9),ISNUMBER(C9)),B9+C9,"") -> 12980.21 | J9: =IF(AND(A9>=2008,ISNUMBER(I9),ISNUMBER(D9)),IF(D9>I9,"Sim","Não"),"") -> Sim
A10: 2009 | B10: 5873.04 | C10: 378.17 | D10: 9910.34 | E10: 3943.08 | F10: 2020.43 | G10: 1027.92 | H10: 664.89 | I10: =IF(AND(ISNUMBER(B10),ISNUMBER(C10)),B10+C10,"") -> 6251.21 | J10: =IF(AND(A10>=2008,ISNUMBER(I10),ISNUMBER(D10)),IF(D10>I10,"Sim","Não"),"") -> Sim
A11: 2010 | B11: 5829.17 | C11: 378.17 | D11: 9910.34 | E11: 3943.08 | F11: 2020.43 | G11: 1027.92 | H11: 664.89 | I11: =IF(AND(ISNUMBER(B11),ISNUMBER(C11)),B11+C11,"") -> 6207.34 | J11: =IF(AND(A11>=2008,ISNUMBER(I11),ISNUMBER(D11)),IF(D11>I11,"Sim","Não"),"") -> Sim
A12: 2011 | B12: 5394.37 | C12: 351.55 | D12: 8976.17 | E12: 4059.43 | F12: 1879.88 | G12: 1699.81 | H12: 510.39 | I12: =IF(AND(ISNUMBER(B12),ISNUMBER(C12)),B12+C12,"") -> 5745.92 | J12: =IF(AND(A12>=2008,ISNUMBER(I12),ISNUMBER(D12)),IF(D12>I12,"Sim","Não"),"") -> Sim
A13: 2012 | B13: 4127.21 | C13: 351.55 | D13: 8976.17 | E13: 3947.56 | F13: 1427.8 | G13: 1125.97 | H13: 429.83 | I13: =IF(AND(ISNUMBER(B13),ISNUMBER(C13)),B13+C13,"") -> 4478.76 | J13: =IF(AND(A13>=2008,ISNUMBER(I13),ISNUMBER(D13)),IF(D13>I13,"Sim","Não"),"") -> Sim
A14: 2013 | B14: 5147.83 | C14: 351.55 | D14: 13481.6 | E14: 3947.56 | F14: 1427.8 | G14: 1125.97 | H14: 429.83 | I14: =IF(AND(ISNUMBER(B14),ISNUMBER(C14)),B14+C14,"") -> 5499.38 | J14: =IF(AND(A14>=2008,ISNUMBER(I14),ISNUMBER(D14)),IF(D14>I14,"Sim","Não"),"") -> Sim
A15: 2014 | B15: 4870.93 | C15: 642.27 | D15: 10904.42 | E15: 3602.16 | F15: 1887.33 | G15: 2118.72 | H15: 369.73 | I15: =IF(AND(ISNUMBER(B15),ISNUMBER(C15)),B15+C15,"") -> 5513.2 | J15: =IF(AND(A15>=2008,ISNUMBER(I15),ISNUMBER(D15)),IF(D15>I15,"Sim","Não"),"") -> Sim
A16: 2015 | B16: 5908.73 | C16: 514.56 | D16: 11131.65 | E16: 2432.87 | F16: 1206.65 | G16: 924.38 | H16: 618.55 | I16: =IF(AND(ISNUMBER(B16),ISNUMBER(C16)),B16+C16,"") -> 6423.29 | J16: =IF(AND(A16>=2008,ISNUMBER(I16),ISNUMBER(D16)),IF(D16>I16,"Sim","Não"),"") -> Sim
A17: 2016 | B17: 7077.57 | C17: 514.56 | D17: 7497.12 | E17: 2432.87 | F17: 1206.65 | G17: 924.38 | H17: 618.55 | I17: =IF(AND(ISNUMBER(B17),ISNUMBER(C17)),B17+C17,"") -> 7592.13 | J17: =IF(AND(A17>=2008,ISNUMBER(I17),ISNUMBER(D17)),IF(D17>I17,"Sim","Não"),"") -> Não
A18: 2017 | B18: 6758.36 | C18: 556.04 | D18: 7117.38 | E18: 2246.17 | F18: 1166.12 | G18: 925.88 | H18: 711.6 | I18: =IF(AND(ISNUMBER(B18),ISNUMBER(C18)),B18+C18,"") -> 7314.4 | J18: =IF(AND(A18>=2008,ISNUMBER(I18),ISNUMBER(D18)),IF(D18>I18,"Sim","Não"),"") -> Não
A19: 2018 | B19: 6957.77 | C19: 556.04 | D19: 7259.82 | E19: 2169.55 | F19: 1344.35 | G19: 917.77 | H19: 498.52 | I19: =IF(AND(ISNUMBER(B19),ISNUMBER(C19)),B19+C19,"") -> 7513.81 | J19: =IF(AND(A19>=2008,ISNUMBER(I19),ISNUMBER(D19)),IF(D19>I19,"Sim","Não"),"") -> Não
A20: 2019 | B20: 10700.58 | C20: 679.65 | D20: 6319.02 | E20: 1868.16 | F20: 1067.37 | G20: 1027.4 | H20: 514.48 | I20: =IF(AND(ISNUMBER(B20),ISNUMBER(C20)),B20+C20,"") -> 11380.23 | J20: =IF(AND(A20>=2008,ISNUMBER(I20),ISNUMBER(D20)),IF(D20>I20,"Sim","Não"),"") -> Não
... A26: 2025 | B26: 5110.68 | C26: 454.08 | D26: 7235.27 | E26: 2289.54 | F26: 402.36 | G26: 305.48 | H26: 291.21 | I26: =IF(AND(ISNUMBER(B26),ISNUMBER(C26)),B26+C26,"") -> 5564.76 | J26: =IF(AND(A26>=2008,ISNUMBER(I26),ISNUMBER(D26)),IF(D26>I26,"Sim","Não"),"") -> Sim
A27: 2026 | B27: 3362.94 | D27: 5516.69 | I27: =IF(AND(ISNUMBER(B27),ISNUMBER(C27)),B27+C27,"") | J27: =IF(AND(A27>=2008,ISNUMBER(I27),ISNUMBER(D27)),IF(D27>I27,"Sim","Não"),"")
A29: Azul = valor copiado do CSV do INPE, sem alteração. Preto = fórmula. Unidade: km². Fonte: INPE/PRODES (TerraBrasilis), acesso em 16/10/2026.

Sheet Base longa
A1: Bioma | B1: Ano | C1: Área desmatada (km²) | D1: Variação anual | E1: Mapeamento bienal
A2: Amazônia (floresta) | B2: 2008 | C2: 12398.68 | E2: não
A3: Amazônia (floresta) | B3: 2009 | C3: 5873.04 | D3: -0.5263 | E3: não
A4: Amazônia (floresta) | B4: 2010 | C4: 5829.17 | D4: -0.0075 | E4: não
A5: Amazônia (floresta) | B5: 2011 | C5: 5394.37 | D5: -0.0746 | E5: não
A6: Amazônia (floresta) | B6: 2012 | C6: 4127.21 | D6: -0.2349 | E6: não
A7: Amazônia (floresta) | B7: 2013 | C7: 5147.83 | D7: 0.2473 | E7: não
A8: Amazônia (floresta) | B8: 2014 | C8: 4870.93 | D8: -0.0538 | E8: não
A9: Amazônia (floresta) | B9: 2015 | C9: 5908.73 | D9: 0.2131 | E9: não
A10: Amazônia (floresta) | B10: 2016 | C10: 7077.57 | D10: 0.1978 | E10: não
A11: Amazônia (floresta) | B11: 2017 | C11: 6758.36 | D11: -0.0451 | E11: não
A12: Amazônia (floresta) | B12: 2018 | C12: 6957.77 | D12: 0.0295 | E12: não
A13: Amazônia (floresta) | B13: 2019 | C13: 10700.58 | D13: 0.5379 | E13: não
A14: Amazônia (floresta) | B14: 2020 | C14: 10351.51 | D14: -0.0326 | E14: não
... A20: Amazônia (floresta) | B20: 2026 | C20: 3362.94 | D20: -0.342 | E20: não
A21: Amazônia (não floresta) | B21: 2001 | C21: 1551.8 | E21: sim
A22: Amazônia (não floresta) | B22: 2002 | C22: 1551.8 | E22: sim
A23: Amazônia (não floresta) | B23: 2003 | C23: 1380.02 | E23: sim
A24: Amazônia (não floresta) | B24: 2004 | C24: 1380.02 | E24: sim
A25: Amazônia (não floresta) | B25: 2005 | C25: 941.24 | E25: sim
A26: Amazônia (não floresta) | B26: 2006 | C26: 941.24 | E26: sim
A27: Amazônia (não floresta) | B27: 2007 | C27: 581.53 | E27: sim
A28: Amazônia (não floresta) | B28: 2008 | C28: 581.53 | E28: sim
A29: Amazônia (não floresta) | B29: 2009 | C29: 378.17 | E29: sim
A30: Amazônia (não floresta) | B30: 2010 | C30: 378.17 | E30: sim
A31: Amazônia (não floresta) | B31: 2011 | C31: 351.55 | E31: sim
A32: Amazônia (não floresta) | B32: 2012 | C32: 351.55 | E32: sim
... A39: Amazônia (não floresta) | B39: 2019 | C39: 679.65 | E39: não
A40: Amazônia (não floresta) | B40: 2020 | C40: 668.55 | D40: -0.0163 | E40: não
A41: Amazônia (não floresta) | B41: 2021 | C41: 719.34 | D41: 0.076 | E41: não
A42: Amazônia (não floresta) | B42: 2022 | C42: 726.33 | D42: 0.0097 | E42: não
A43: Amazônia (não floresta) | B43: 2023 | C43: 584.82 | D43: -0.1948 | E43: não
A44: Amazônia (não floresta) | B44: 2024 | C44: 554.04 | D44: -0.0526 | E44: não
A45: Amazônia (não floresta) | B45: 2025 | C45: 454.08 | D45: -0.1804 | E45: não
A46: Caatinga | B46: 2001 | C46: 12186.41 | E46: sim
A47: Caatinga | B47: 2002 | C47: 12186.41 | E47: sim
A48: Caatinga | B48: 2003 | C48: 12186.41 | E48: sim
A49: Caatinga | B49: 2004 | C49: 12186.41 | E49: sim
A50: Caatinga | B50: 2005 | C50: 8172.6 | E50: sim
A51: Caatinga | B51: 2006 | C51: 8172.6 | E51: sim
...

Sheet Conferência
A1: Conferência dos números do post #1
A2: Coluna C = calculado por fórmula a partir da aba Tabela anual. Coluna D = número citado no post. Coluna E confere se batem.
A4: # | B4: Número do post | C4: Calculado (fórmula) | D4: Citado no post | E4: Bate? | F4: Como é calculado
A5: 1 | B5: Anos (2008–2025) em que o Cerrado desmatou mais que a Amazônia | C5: =COUNTIF('Tabela anual'!J9:J26,"Sim") -> 11 | D5: 11 | E5: =IF(ABS(C5-D5)<=0,"✓ Sim","✗ Não") -> ✓ Sim | F5: Conta "Sim" na coluna J da Tabela anual
A6: 1b | B6: Anos (2008–2025) em que a Amazônia desmatou mais | C6: =COUNTIF('Tabela anual'!J9:J26,"Não") -> 7 | D6: 7 | E6: =IF(ABS(C6-D6)<=0,"✓ Sim","✗ Não") -> ✓ Sim | F6: Devem ser 2016 a 2022
A7: 2a | B7: Amazônia (floresta) em 2022, km² | C7: ='Tabela anual'!B23 -> 12473.98 | D7: 12474 | E7: =IF(ABS(C7-D7)<=0.5,"✓ Sim","✗ Não") -> ✓ Sim | F7: Valor do INPE
A8: 2b | B8: Amazônia (floresta) em 2026, km² | C8: ='Tabela anual'!B27 -> 3362.94 | D8: 3363 | E8: =IF(ABS(C8-D8)<=0.5,"✓ Sim","✗ Não") -> ✓ Sim | F8: Valor do INPE
A9: 2c | B9: Queda 2022 → 2026 | C9: ='Tabela anual'!B27/'Tabela anual'!B23-1 -> -0.73040361 | D9: -0.73 | E9: =IF(ABS(C9-D9)<=0.005,"✓ Sim","✗ Não") -> ✓ Sim | F9: 2026 ÷ 2022 − 1
A10: 3a | B10: Desmatamento total no país em 2025, km² | C10: =SUM('Tabela anual'!B26:H26) -> 16088.62 | D10: 16089 | E10: =IF(ABS(C10-D10)<=0.5,"✓ Sim","✗ Não") -> ✓ Sim | F10: Soma dos 7 biomas/classes
A11: 3b | B11: Participação do Cerrado em 2025 | C11: ='Tabela anual'!D26/SUM('Tabela anual'!B26:H26) -> 0.44971352 | D11: 0.45 | E11: =IF(ABS(C11-D11)<=0.005,"✓ Sim","✗ Não") -> ✓ Sim | F11: Cerrado ÷ total
A12: 4a | B12: Cerrado acumulado 2008–2025, km² | C12: =SUM('Tabela anual'!D9:D26) -> 168339.42 | D12: 168339 | E12: =IF(ABS(C12-D12)<=0.5,"✓ Sim","✗ Não") -> ✓ Sim | F12: Soma da coluna Cerrado
A13: 4b | B13: Amazônia total acumulada 2008–2025, km² | C13: =SUM('Tabela anual'!I9:I26) -> 144597.5 | D13: 144598 | E13: =IF(ABS(C13-D13)<=0.5,"✓ Sim","✗ Não") -> ✓ Sim | F13: Soma da coluna Amazônia total
